2018-06-20 13:00:28,316 INFO: Microblog startup [in C:\GardenApp\app\__init__.py:76]
2018-06-20 13:00:35,312 INFO: Microblog startup [in C:\GardenApp\app\__init__.py:76]
2018-06-20 13:00:45,006 INFO: Microblog startup [in C:\GardenApp\app\__init__.py:76]
2018-06-20 13:00:52,085 INFO: Microblog startup [in C:\GardenApp\app\__init__.py:76]
2018-06-20 13:21:03,538 INFO: Microblog startup [in C:\GardenApp\app\__init__.py:76]
2018-06-20 13:31:07,706 INFO: Microblog startup [in C:\GardenApp\app\__init__.py:76]
2018-06-20 13:31:12,633 INFO: Microblog startup [in C:\GardenApp\app\__init__.py:76]
2018-06-20 13:31:20,215 INFO: Microblog startup [in C:\GardenApp\app\__init__.py:76]
2018-06-20 13:40:23,127 INFO: Microblog startup [in C:\GardenApp\app\__init__.py:76]
2018-06-20 16:34:12,677 INFO: Microblog startup [in C:\GardenApp\app\__init__.py:76]
2018-06-20 17:21:26,605 INFO: Microblog startup [in C:\GardenApp\app\__init__.py:76]
2018-06-20 17:21:48,449 INFO: Microblog startup [in C:\GardenApp\app\__init__.py:76]
2018-06-20 17:22:25,887 ERROR: Exception on /api/posts/3 [GET] [in c:\gardenapp\blogvenv\lib\site-packages\flask\app.py:1560]
Traceback (most recent call last):
  File "c:\gardenapp\blogvenv\lib\site-packages\flask\app.py", line 1982, in wsgi_app
    response = self.full_dispatch_request()
  File "c:\gardenapp\blogvenv\lib\site-packages\flask\app.py", line 1614, in full_dispatch_request
    rv = self.handle_user_exception(e)
  File "c:\gardenapp\blogvenv\lib\site-packages\flask\app.py", line 1517, in handle_user_exception
    reraise(exc_type, exc_value, tb)
  File "c:\gardenapp\blogvenv\lib\site-packages\flask\_compat.py", line 33, in reraise
    raise value
  File "c:\gardenapp\blogvenv\lib\site-packages\flask\app.py", line 1612, in full_dispatch_request
    rv = self.dispatch_request()
  File "c:\gardenapp\blogvenv\lib\site-packages\flask\app.py", line 1598, in dispatch_request
    return self.view_functions[rule.endpoint](**req.view_args)
  File "c:\gardenapp\blogvenv\lib\site-packages\flask_httpauth.py", line 93, in decorated
    return f(*args, **kwargs)
TypeError: get_posts_by_user() got an unexpected keyword argument 'id'
2018-06-20 17:40:11,321 INFO: Microblog startup [in C:\GardenApp\app\__init__.py:76]
2018-06-20 17:40:39,813 INFO: Microblog startup [in C:\GardenApp\app\__init__.py:76]
2018-06-20 17:41:24,217 ERROR: Exception on /api/posts/3 [GET] [in c:\gardenapp\blogvenv\lib\site-packages\flask\app.py:1560]
Traceback (most recent call last):
  File "c:\gardenapp\blogvenv\lib\site-packages\flask\app.py", line 1982, in wsgi_app
    response = self.full_dispatch_request()
  File "c:\gardenapp\blogvenv\lib\site-packages\flask\app.py", line 1614, in full_dispatch_request
    rv = self.handle_user_exception(e)
  File "c:\gardenapp\blogvenv\lib\site-packages\flask\app.py", line 1517, in handle_user_exception
    reraise(exc_type, exc_value, tb)
  File "c:\gardenapp\blogvenv\lib\site-packages\flask\_compat.py", line 33, in reraise
    raise value
  File "c:\gardenapp\blogvenv\lib\site-packages\flask\app.py", line 1612, in full_dispatch_request
    rv = self.dispatch_request()
  File "c:\gardenapp\blogvenv\lib\site-packages\flask\app.py", line 1598, in dispatch_request
    return self.view_functions[rule.endpoint](**req.view_args)
  File "c:\gardenapp\blogvenv\lib\site-packages\flask_httpauth.py", line 93, in decorated
    return f(*args, **kwargs)
  File "C:\GardenApp\app\api\posts.py", line 23, in get_posts_by_user
    data = Post.to_collection_dict(Post.query.filter_by(user_id=id), page, per_page, 'api.get_posts_by_user')
  File "C:\GardenApp\app\models.py", line 28, in to_collection_dict
    **kwargs),
  File "c:\gardenapp\blogvenv\lib\site-packages\flask\helpers.py", line 333, in url_for
    return appctx.app.handle_url_build_error(error, endpoint, values)
  File "c:\gardenapp\blogvenv\lib\site-packages\flask\app.py", line 1805, in handle_url_build_error
    reraise(exc_type, exc_value, tb)
  File "c:\gardenapp\blogvenv\lib\site-packages\flask\_compat.py", line 33, in reraise
    raise value
  File "c:\gardenapp\blogvenv\lib\site-packages\flask\helpers.py", line 323, in url_for
    force_external=external)
  File "c:\gardenapp\blogvenv\lib\site-packages\werkzeug\routing.py", line 1776, in build
    raise BuildError(endpoint, values, method, self)
werkzeug.routing.BuildError: Could not build url for endpoint 'api.get_posts_by_user' with values ['page', 'per_page']. Did you forget to specify values ['id']?
2018-06-20 17:43:52,359 INFO: Microblog startup [in C:\GardenApp\app\__init__.py:76]
2018-06-20 17:43:58,731 ERROR: Exception on /api/posts/3 [GET] [in c:\gardenapp\blogvenv\lib\site-packages\flask\app.py:1560]
Traceback (most recent call last):
  File "c:\gardenapp\blogvenv\lib\site-packages\flask\app.py", line 1982, in wsgi_app
    response = self.full_dispatch_request()
  File "c:\gardenapp\blogvenv\lib\site-packages\flask\app.py", line 1614, in full_dispatch_request
    rv = self.handle_user_exception(e)
  File "c:\gardenapp\blogvenv\lib\site-packages\flask\app.py", line 1517, in handle_user_exception
    reraise(exc_type, exc_value, tb)
  File "c:\gardenapp\blogvenv\lib\site-packages\flask\_compat.py", line 33, in reraise
    raise value
  File "c:\gardenapp\blogvenv\lib\site-packages\flask\app.py", line 1612, in full_dispatch_request
    rv = self.dispatch_request()
  File "c:\gardenapp\blogvenv\lib\site-packages\flask\app.py", line 1598, in dispatch_request
    return self.view_functions[rule.endpoint](**req.view_args)
  File "c:\gardenapp\blogvenv\lib\site-packages\flask_httpauth.py", line 93, in decorated
    return f(*args, **kwargs)
  File "C:\GardenApp\app\api\posts.py", line 24, in get_posts_by_user
    data = Post.to_collection_dict(user.posts, page, per_page, 'api.get_posts_by_user')
  File "C:\GardenApp\app\models.py", line 28, in to_collection_dict
    **kwargs),
  File "c:\gardenapp\blogvenv\lib\site-packages\flask\helpers.py", line 333, in url_for
    return appctx.app.handle_url_build_error(error, endpoint, values)
  File "c:\gardenapp\blogvenv\lib\site-packages\flask\app.py", line 1805, in handle_url_build_error
    reraise(exc_type, exc_value, tb)
  File "c:\gardenapp\blogvenv\lib\site-packages\flask\_compat.py", line 33, in reraise
    raise value
  File "c:\gardenapp\blogvenv\lib\site-packages\flask\helpers.py", line 323, in url_for
    force_external=external)
  File "c:\gardenapp\blogvenv\lib\site-packages\werkzeug\routing.py", line 1776, in build
    raise BuildError(endpoint, values, method, self)
werkzeug.routing.BuildError: Could not build url for endpoint 'api.get_posts_by_user' with values ['page', 'per_page']. Did you forget to specify values ['id']?
2018-06-20 17:44:46,663 ERROR: Exception on /api/posts/3 [GET] [in c:\gardenapp\blogvenv\lib\site-packages\flask\app.py:1560]
Traceback (most recent call last):
  File "c:\gardenapp\blogvenv\lib\site-packages\flask\app.py", line 1982, in wsgi_app
    response = self.full_dispatch_request()
  File "c:\gardenapp\blogvenv\lib\site-packages\flask\app.py", line 1614, in full_dispatch_request
    rv = self.handle_user_exception(e)
  File "c:\gardenapp\blogvenv\lib\site-packages\flask\app.py", line 1517, in handle_user_exception
    reraise(exc_type, exc_value, tb)
  File "c:\gardenapp\blogvenv\lib\site-packages\flask\_compat.py", line 33, in reraise
    raise value
  File "c:\gardenapp\blogvenv\lib\site-packages\flask\app.py", line 1612, in full_dispatch_request
    rv = self.dispatch_request()
  File "c:\gardenapp\blogvenv\lib\site-packages\flask\app.py", line 1598, in dispatch_request
    return self.view_functions[rule.endpoint](**req.view_args)
  File "c:\gardenapp\blogvenv\lib\site-packages\flask_httpauth.py", line 93, in decorated
    return f(*args, **kwargs)
  File "C:\GardenApp\app\api\posts.py", line 24, in get_posts_by_user
    data = User.to_collection_dict(user.posts, page, per_page, 'api.get_posts_by_user')
  File "C:\GardenApp\app\models.py", line 28, in to_collection_dict
    **kwargs),
  File "c:\gardenapp\blogvenv\lib\site-packages\flask\helpers.py", line 333, in url_for
    return appctx.app.handle_url_build_error(error, endpoint, values)
  File "c:\gardenapp\blogvenv\lib\site-packages\flask\app.py", line 1805, in handle_url_build_error
    reraise(exc_type, exc_value, tb)
  File "c:\gardenapp\blogvenv\lib\site-packages\flask\_compat.py", line 33, in reraise
    raise value
  File "c:\gardenapp\blogvenv\lib\site-packages\flask\helpers.py", line 323, in url_for
    force_external=external)
  File "c:\gardenapp\blogvenv\lib\site-packages\werkzeug\routing.py", line 1776, in build
    raise BuildError(endpoint, values, method, self)
werkzeug.routing.BuildError: Could not build url for endpoint 'api.get_posts_by_user' with values ['page', 'per_page']. Did you forget to specify values ['id']?
2018-06-20 17:44:53,111 INFO: Microblog startup [in C:\GardenApp\app\__init__.py:76]
2018-06-20 17:45:55,949 INFO: Microblog startup [in C:\GardenApp\app\__init__.py:76]
2018-06-20 17:47:10,234 INFO: Microblog startup [in C:\GardenApp\app\__init__.py:76]
2018-06-20 17:50:13,844 INFO: Microblog startup [in C:\GardenApp\app\__init__.py:76]
2018-06-20 17:50:19,716 INFO: Microblog startup [in C:\GardenApp\app\__init__.py:76]
2018-06-20 17:54:10,142 INFO: Microblog startup [in C:\GardenApp\app\__init__.py:76]
