2019-02-25 14:55:04,717 INFO: Microblog startup [in C:\GardenApp\app\__init__.py:76]
2019-02-25 15:57:33,022 INFO: Microblog startup [in C:\GardenApp\app\__init__.py:76]
2019-02-25 17:24:24,122 INFO: Microblog startup [in C:\GardenApp\app\__init__.py:76]
2019-03-12 00:54:12,933 INFO: Microblog startup [in C:\GardenApp\app\__init__.py:76]
2019-03-12 00:56:36,711 INFO: Microblog startup [in C:\GardenApp\app\__init__.py:76]
2019-03-20 14:02:12,874 INFO: Microblog startup [in C:\GardenApp\app\__init__.py:76]
2019-03-20 14:05:21,703 ERROR: Exception on /api/user/reverse_geocode [POST] [in c:\gardenapp\blogvenv\lib\site-packages\flask\app.py:1560]
Traceback (most recent call last):
  File "c:\gardenapp\blogvenv\lib\site-packages\flask\app.py", line 1982, in wsgi_app
    response = self.full_dispatch_request()
  File "c:\gardenapp\blogvenv\lib\site-packages\flask\app.py", line 1614, in full_dispatch_request
    rv = self.handle_user_exception(e)
  File "c:\gardenapp\blogvenv\lib\site-packages\flask\app.py", line 1517, in handle_user_exception
    reraise(exc_type, exc_value, tb)
  File "c:\gardenapp\blogvenv\lib\site-packages\flask\_compat.py", line 33, in reraise
    raise value
  File "c:\gardenapp\blogvenv\lib\site-packages\flask\app.py", line 1612, in full_dispatch_request
    rv = self.dispatch_request()
  File "c:\gardenapp\blogvenv\lib\site-packages\flask\app.py", line 1598, in dispatch_request
    return self.view_functions[rule.endpoint](**req.view_args)
  File "c:\gardenapp\blogvenv\lib\site-packages\flask_httpauth.py", line 93, in decorated
    return f(*args, **kwargs)
  File "C:\GardenApp\app\api\gardens.py", line 61, in reverse_geocode_by_token
    lat = data['lat']
KeyError: 'lat'
2019-03-20 14:05:47,077 ERROR: Exception on /api/user/reverse_geocode [POST] [in c:\gardenapp\blogvenv\lib\site-packages\flask\app.py:1560]
Traceback (most recent call last):
  File "c:\gardenapp\blogvenv\lib\site-packages\flask\app.py", line 1982, in wsgi_app
    response = self.full_dispatch_request()
  File "c:\gardenapp\blogvenv\lib\site-packages\flask\app.py", line 1614, in full_dispatch_request
    rv = self.handle_user_exception(e)
  File "c:\gardenapp\blogvenv\lib\site-packages\flask\app.py", line 1517, in handle_user_exception
    reraise(exc_type, exc_value, tb)
  File "c:\gardenapp\blogvenv\lib\site-packages\flask\_compat.py", line 33, in reraise
    raise value
  File "c:\gardenapp\blogvenv\lib\site-packages\flask\app.py", line 1612, in full_dispatch_request
    rv = self.dispatch_request()
  File "c:\gardenapp\blogvenv\lib\site-packages\flask\app.py", line 1598, in dispatch_request
    return self.view_functions[rule.endpoint](**req.view_args)
  File "c:\gardenapp\blogvenv\lib\site-packages\flask_httpauth.py", line 93, in decorated
    return f(*args, **kwargs)
  File "C:\GardenApp\app\api\gardens.py", line 61, in reverse_geocode_by_token
    lat = data['lat']
KeyError: 'lat'
2019-03-20 14:05:58,134 ERROR: Exception on /api/user/reverse_geocode [POST] [in c:\gardenapp\blogvenv\lib\site-packages\flask\app.py:1560]
Traceback (most recent call last):
  File "c:\gardenapp\blogvenv\lib\site-packages\flask\app.py", line 1982, in wsgi_app
    response = self.full_dispatch_request()
  File "c:\gardenapp\blogvenv\lib\site-packages\flask\app.py", line 1614, in full_dispatch_request
    rv = self.handle_user_exception(e)
  File "c:\gardenapp\blogvenv\lib\site-packages\flask\app.py", line 1517, in handle_user_exception
    reraise(exc_type, exc_value, tb)
  File "c:\gardenapp\blogvenv\lib\site-packages\flask\_compat.py", line 33, in reraise
    raise value
  File "c:\gardenapp\blogvenv\lib\site-packages\flask\app.py", line 1612, in full_dispatch_request
    rv = self.dispatch_request()
  File "c:\gardenapp\blogvenv\lib\site-packages\flask\app.py", line 1598, in dispatch_request
    return self.view_functions[rule.endpoint](**req.view_args)
  File "c:\gardenapp\blogvenv\lib\site-packages\flask_httpauth.py", line 93, in decorated
    return f(*args, **kwargs)
  File "C:\GardenApp\app\api\gardens.py", line 61, in reverse_geocode_by_token
    lat = data['lat']
KeyError: 'lat'
2019-03-20 14:07:02,837 INFO: Microblog startup [in C:\GardenApp\app\__init__.py:76]
2019-03-20 14:07:06,186 ERROR: Exception on /api/user/reverse_geocode [POST] [in c:\gardenapp\blogvenv\lib\site-packages\flask\app.py:1560]
Traceback (most recent call last):
  File "c:\gardenapp\blogvenv\lib\site-packages\flask\app.py", line 1982, in wsgi_app
    response = self.full_dispatch_request()
  File "c:\gardenapp\blogvenv\lib\site-packages\flask\app.py", line 1614, in full_dispatch_request
    rv = self.handle_user_exception(e)
  File "c:\gardenapp\blogvenv\lib\site-packages\flask\app.py", line 1517, in handle_user_exception
    reraise(exc_type, exc_value, tb)
  File "c:\gardenapp\blogvenv\lib\site-packages\flask\_compat.py", line 33, in reraise
    raise value
  File "c:\gardenapp\blogvenv\lib\site-packages\flask\app.py", line 1612, in full_dispatch_request
    rv = self.dispatch_request()
  File "c:\gardenapp\blogvenv\lib\site-packages\flask\app.py", line 1598, in dispatch_request
    return self.view_functions[rule.endpoint](**req.view_args)
  File "c:\gardenapp\blogvenv\lib\site-packages\flask_httpauth.py", line 93, in decorated
    return f(*args, **kwargs)
  File "C:\GardenApp\app\api\gardens.py", line 59, in reverse_geocode_by_token
    lat = data['lat']
KeyError: 'lat'
2019-03-20 14:08:44,560 INFO: Microblog startup [in C:\GardenApp\app\__init__.py:76]
2019-03-20 14:08:49,944 ERROR: Exception on /api/user/reverse_geocode [POST] [in c:\gardenapp\blogvenv\lib\site-packages\flask\app.py:1560]
Traceback (most recent call last):
  File "c:\gardenapp\blogvenv\lib\site-packages\flask\app.py", line 1982, in wsgi_app
    response = self.full_dispatch_request()
  File "c:\gardenapp\blogvenv\lib\site-packages\flask\app.py", line 1614, in full_dispatch_request
    rv = self.handle_user_exception(e)
  File "c:\gardenapp\blogvenv\lib\site-packages\flask\app.py", line 1517, in handle_user_exception
    reraise(exc_type, exc_value, tb)
  File "c:\gardenapp\blogvenv\lib\site-packages\flask\_compat.py", line 33, in reraise
    raise value
  File "c:\gardenapp\blogvenv\lib\site-packages\flask\app.py", line 1612, in full_dispatch_request
    rv = self.dispatch_request()
  File "c:\gardenapp\blogvenv\lib\site-packages\flask\app.py", line 1598, in dispatch_request
    return self.view_functions[rule.endpoint](**req.view_args)
  File "c:\gardenapp\blogvenv\lib\site-packages\flask_httpauth.py", line 93, in decorated
    return f(*args, **kwargs)
  File "C:\GardenApp\app\api\gardens.py", line 60, in reverse_geocode_by_token
    lat = data['lat']
KeyError: 'lat'
2019-03-20 14:09:56,926 ERROR: Exception on /api/user/reverse_geocode [POST] [in c:\gardenapp\blogvenv\lib\site-packages\flask\app.py:1560]
Traceback (most recent call last):
  File "c:\gardenapp\blogvenv\lib\site-packages\flask\app.py", line 1982, in wsgi_app
    response = self.full_dispatch_request()
  File "c:\gardenapp\blogvenv\lib\site-packages\flask\app.py", line 1614, in full_dispatch_request
    rv = self.handle_user_exception(e)
  File "c:\gardenapp\blogvenv\lib\site-packages\flask\app.py", line 1517, in handle_user_exception
    reraise(exc_type, exc_value, tb)
  File "c:\gardenapp\blogvenv\lib\site-packages\flask\_compat.py", line 33, in reraise
    raise value
  File "c:\gardenapp\blogvenv\lib\site-packages\flask\app.py", line 1612, in full_dispatch_request
    rv = self.dispatch_request()
  File "c:\gardenapp\blogvenv\lib\site-packages\flask\app.py", line 1598, in dispatch_request
    return self.view_functions[rule.endpoint](**req.view_args)
  File "c:\gardenapp\blogvenv\lib\site-packages\flask_httpauth.py", line 93, in decorated
    return f(*args, **kwargs)
  File "C:\GardenApp\app\api\gardens.py", line 79, in reverse_geocode_by_token
    for r in responseJSON.results:
AttributeError: 'dict' object has no attribute 'results'
2019-03-20 14:11:06,119 INFO: Microblog startup [in C:\GardenApp\app\__init__.py:76]
2019-03-20 14:11:11,129 ERROR: Exception on /api/user/reverse_geocode [POST] [in c:\gardenapp\blogvenv\lib\site-packages\flask\app.py:1560]
Traceback (most recent call last):
  File "c:\gardenapp\blogvenv\lib\site-packages\flask\app.py", line 1982, in wsgi_app
    response = self.full_dispatch_request()
  File "c:\gardenapp\blogvenv\lib\site-packages\flask\app.py", line 1615, in full_dispatch_request
    return self.finalize_request(rv)
  File "c:\gardenapp\blogvenv\lib\site-packages\flask\app.py", line 1630, in finalize_request
    response = self.make_response(rv)
  File "c:\gardenapp\blogvenv\lib\site-packages\flask\app.py", line 1740, in make_response
    rv = self.response_class.force_type(rv, request.environ)
  File "c:\gardenapp\blogvenv\lib\site-packages\werkzeug\wrappers.py", line 921, in force_type
    response = BaseResponse(*_run_wsgi_app(response, environ))
  File "c:\gardenapp\blogvenv\lib\site-packages\werkzeug\wrappers.py", line 59, in _run_wsgi_app
    return _run_wsgi_app(*args)
  File "c:\gardenapp\blogvenv\lib\site-packages\werkzeug\test.py", line 923, in run_wsgi_app
    app_rv = app(environ, start_response)
TypeError: 'dict' object is not callable
2019-03-20 14:11:38,917 INFO: Microblog startup [in C:\GardenApp\app\__init__.py:76]
