2018-06-12 14:58:15,748 ERROR: Exception on /api/users [GET] [in c:\gardenapp\blogvenv\lib\site-packages\flask\app.py:1560]
Traceback (most recent call last):
  File "c:\gardenapp\blogvenv\lib\site-packages\flask\app.py", line 1982, in wsgi_app
    response = self.full_dispatch_request()
  File "c:\gardenapp\blogvenv\lib\site-packages\flask\app.py", line 1614, in full_dispatch_request
    rv = self.handle_user_exception(e)
  File "c:\gardenapp\blogvenv\lib\site-packages\flask\app.py", line 1517, in handle_user_exception
    reraise(exc_type, exc_value, tb)
  File "c:\gardenapp\blogvenv\lib\site-packages\flask\_compat.py", line 33, in reraise
    raise value
  File "c:\gardenapp\blogvenv\lib\site-packages\flask\app.py", line 1612, in full_dispatch_request
    rv = self.dispatch_request()
  File "c:\gardenapp\blogvenv\lib\site-packages\flask\app.py", line 1598, in dispatch_request
    return self.view_functions[rule.endpoint](**req.view_args)
  File "C:\GardenApp\app\api\users.py", line 11, in get_users
    page = request.args.get('page', 1, type=int)
NameError: name 'request' is not defined
2018-06-12 14:58:36,923 INFO: Microblog startup [in C:\GardenApp\app\__init__.py:76]
2018-06-12 15:02:51,049 INFO: Microblog startup [in C:\GardenApp\app\__init__.py:76]
2018-06-12 15:03:17,926 INFO: Microblog startup [in C:\GardenApp\app\__init__.py:76]
2018-06-12 16:45:46,500 INFO: Microblog startup [in C:\GardenApp\app\__init__.py:76]
2018-06-12 16:46:14,354 INFO: Microblog startup [in C:\GardenApp\app\__init__.py:76]
2018-06-12 16:52:36,567 INFO: Microblog startup [in C:\GardenApp\app\__init__.py:76]
2018-06-12 16:54:59,750 INFO: Microblog startup [in C:\GardenApp\app\__init__.py:76]
2018-06-12 17:00:29,233 INFO: Microblog startup [in C:\GardenApp\app\__init__.py:76]
2018-06-12 17:00:39,552 INFO: Microblog startup [in C:\GardenApp\app\__init__.py:76]
2018-06-12 21:11:53,112 INFO: Microblog startup [in C:\GardenApp\app\__init__.py:76]
2018-06-12 21:12:16,146 INFO: Microblog startup [in C:\GardenApp\app\__init__.py:76]
2018-06-12 21:21:11,692 ERROR: Exception on /api/users [POST] [in c:\gardenapp\blogvenv\lib\site-packages\flask\app.py:1560]
Traceback (most recent call last):
  File "c:\gardenapp\blogvenv\lib\site-packages\flask\app.py", line 1982, in wsgi_app
    response = self.full_dispatch_request()
  File "c:\gardenapp\blogvenv\lib\site-packages\flask\app.py", line 1614, in full_dispatch_request
    rv = self.handle_user_exception(e)
  File "c:\gardenapp\blogvenv\lib\site-packages\flask\app.py", line 1517, in handle_user_exception
    reraise(exc_type, exc_value, tb)
  File "c:\gardenapp\blogvenv\lib\site-packages\flask\_compat.py", line 33, in reraise
    raise value
  File "c:\gardenapp\blogvenv\lib\site-packages\flask\app.py", line 1612, in full_dispatch_request
    rv = self.dispatch_request()
  File "c:\gardenapp\blogvenv\lib\site-packages\flask\app.py", line 1598, in dispatch_request
    return self.view_functions[rule.endpoint](**req.view_args)
  File "C:\GardenApp\app\api\users.py", line 51, in create_user
    response.headers['Location'] = url_for('api.get_user', id=user.id)
NameError: name 'url_for' is not defined
2018-06-12 21:24:14,011 ERROR: Exception on /api/users [POST] [in c:\gardenapp\blogvenv\lib\site-packages\flask\app.py:1560]
Traceback (most recent call last):
  File "c:\gardenapp\blogvenv\lib\site-packages\flask\app.py", line 1982, in wsgi_app
    response = self.full_dispatch_request()
  File "c:\gardenapp\blogvenv\lib\site-packages\flask\app.py", line 1614, in full_dispatch_request
    rv = self.handle_user_exception(e)
  File "c:\gardenapp\blogvenv\lib\site-packages\flask\app.py", line 1517, in handle_user_exception
    reraise(exc_type, exc_value, tb)
  File "c:\gardenapp\blogvenv\lib\site-packages\flask\_compat.py", line 33, in reraise
    raise value
  File "c:\gardenapp\blogvenv\lib\site-packages\flask\app.py", line 1612, in full_dispatch_request
    rv = self.dispatch_request()
  File "c:\gardenapp\blogvenv\lib\site-packages\flask\app.py", line 1598, in dispatch_request
    return self.view_functions[rule.endpoint](**req.view_args)
  File "C:\GardenApp\app\api\users.py", line 42, in create_user
    return bad_request('please use a different username')
TypeError: bad_request() takes 0 positional arguments but 1 was given
2018-06-12 21:24:37,532 ERROR: Exception on /api/users [POST] [in c:\gardenapp\blogvenv\lib\site-packages\flask\app.py:1560]
Traceback (most recent call last):
  File "c:\gardenapp\blogvenv\lib\site-packages\flask\app.py", line 1982, in wsgi_app
    response = self.full_dispatch_request()
  File "c:\gardenapp\blogvenv\lib\site-packages\flask\app.py", line 1614, in full_dispatch_request
    rv = self.handle_user_exception(e)
  File "c:\gardenapp\blogvenv\lib\site-packages\flask\app.py", line 1517, in handle_user_exception
    reraise(exc_type, exc_value, tb)
  File "c:\gardenapp\blogvenv\lib\site-packages\flask\_compat.py", line 33, in reraise
    raise value
  File "c:\gardenapp\blogvenv\lib\site-packages\flask\app.py", line 1612, in full_dispatch_request
    rv = self.dispatch_request()
  File "c:\gardenapp\blogvenv\lib\site-packages\flask\app.py", line 1598, in dispatch_request
    return self.view_functions[rule.endpoint](**req.view_args)
  File "C:\GardenApp\app\api\users.py", line 42, in create_user
    return bad_request('please use a different username')
TypeError: bad_request() takes 0 positional arguments but 1 was given
2018-06-12 21:26:15,118 ERROR: Exception on /api/users [POST] [in c:\gardenapp\blogvenv\lib\site-packages\flask\app.py:1560]
Traceback (most recent call last):
  File "c:\gardenapp\blogvenv\lib\site-packages\flask\app.py", line 1982, in wsgi_app
    response = self.full_dispatch_request()
  File "c:\gardenapp\blogvenv\lib\site-packages\flask\app.py", line 1614, in full_dispatch_request
    rv = self.handle_user_exception(e)
  File "c:\gardenapp\blogvenv\lib\site-packages\flask\app.py", line 1517, in handle_user_exception
    reraise(exc_type, exc_value, tb)
  File "c:\gardenapp\blogvenv\lib\site-packages\flask\_compat.py", line 33, in reraise
    raise value
  File "c:\gardenapp\blogvenv\lib\site-packages\flask\app.py", line 1612, in full_dispatch_request
    rv = self.dispatch_request()
  File "c:\gardenapp\blogvenv\lib\site-packages\flask\app.py", line 1598, in dispatch_request
    return self.view_functions[rule.endpoint](**req.view_args)
  File "C:\GardenApp\app\api\users.py", line 40, in create_user
    return bad_request('must include username, email and password fields')
TypeError: bad_request() takes 0 positional arguments but 1 was given
2018-06-12 21:28:51,479 ERROR: Exception on /api/users [POST] [in c:\gardenapp\blogvenv\lib\site-packages\flask\app.py:1560]
Traceback (most recent call last):
  File "c:\gardenapp\blogvenv\lib\site-packages\flask\app.py", line 1982, in wsgi_app
    response = self.full_dispatch_request()
  File "c:\gardenapp\blogvenv\lib\site-packages\flask\app.py", line 1614, in full_dispatch_request
    rv = self.handle_user_exception(e)
  File "c:\gardenapp\blogvenv\lib\site-packages\flask\app.py", line 1517, in handle_user_exception
    reraise(exc_type, exc_value, tb)
  File "c:\gardenapp\blogvenv\lib\site-packages\flask\_compat.py", line 33, in reraise
    raise value
  File "c:\gardenapp\blogvenv\lib\site-packages\flask\app.py", line 1612, in full_dispatch_request
    rv = self.dispatch_request()
  File "c:\gardenapp\blogvenv\lib\site-packages\flask\app.py", line 1598, in dispatch_request
    return self.view_functions[rule.endpoint](**req.view_args)
  File "C:\GardenApp\app\api\users.py", line 40, in create_user
    return bad_request('must include username, email and password fields')
TypeError: bad_request() takes 0 positional arguments but 1 was given
2018-06-12 21:29:32,135 ERROR: Exception on /api/users [POST] [in c:\gardenapp\blogvenv\lib\site-packages\flask\app.py:1560]
Traceback (most recent call last):
  File "c:\gardenapp\blogvenv\lib\site-packages\flask\app.py", line 1982, in wsgi_app
    response = self.full_dispatch_request()
  File "c:\gardenapp\blogvenv\lib\site-packages\flask\app.py", line 1614, in full_dispatch_request
    rv = self.handle_user_exception(e)
  File "c:\gardenapp\blogvenv\lib\site-packages\flask\app.py", line 1517, in handle_user_exception
    reraise(exc_type, exc_value, tb)
  File "c:\gardenapp\blogvenv\lib\site-packages\flask\_compat.py", line 33, in reraise
    raise value
  File "c:\gardenapp\blogvenv\lib\site-packages\flask\app.py", line 1612, in full_dispatch_request
    rv = self.dispatch_request()
  File "c:\gardenapp\blogvenv\lib\site-packages\flask\app.py", line 1598, in dispatch_request
    return self.view_functions[rule.endpoint](**req.view_args)
  File "C:\GardenApp\app\api\users.py", line 40, in create_user
    return bad_request('must include username, email and password fields')
TypeError: bad_request() takes 0 positional arguments but 1 was given
2018-06-12 21:59:23,865 ERROR: Exception on /api/users/2 [PUT] [in c:\gardenapp\blogvenv\lib\site-packages\flask\app.py:1560]
Traceback (most recent call last):
  File "c:\gardenapp\blogvenv\lib\site-packages\flask\app.py", line 1982, in wsgi_app
    response = self.full_dispatch_request()
  File "c:\gardenapp\blogvenv\lib\site-packages\flask\app.py", line 1615, in full_dispatch_request
    return self.finalize_request(rv)
  File "c:\gardenapp\blogvenv\lib\site-packages\flask\app.py", line 1630, in finalize_request
    response = self.make_response(rv)
  File "c:\gardenapp\blogvenv\lib\site-packages\flask\app.py", line 1725, in make_response
    raise ValueError('View function did not return a response')
ValueError: View function did not return a response
2018-06-13 13:34:06,611 INFO: Microblog startup [in C:\GardenApp\app\__init__.py:76]
2018-06-13 13:35:14,960 INFO: Microblog startup [in C:\GardenApp\app\__init__.py:76]
2018-06-13 21:54:36,516 INFO: Microblog startup [in C:\GardenApp\app\__init__.py:76]
2018-06-13 21:54:46,397 INFO: Microblog startup [in C:\GardenApp\app\__init__.py:76]
